<?xml version="1.0" encoding="UTF-8"?>
<testng-results ignored="0" total="2" passed="1" failed="1" skipped="0">
  <reporter-output>
  </reporter-output>
  <suite started-at="2025-10-05T12:52:30 IST" name="SampleTestSuite" finished-at="2025-10-05T12:52:30 IST" duration-ms="73">
    <groups>
    </groups>
    <test started-at="2025-10-05T12:52:30 IST" name="SampleTest" finished-at="2025-10-05T12:52:30 IST" duration-ms="73">
      <class name="com.example.mytestcase.AppTest">
        <test-method is-config="true" signature="setup()[pri:0, instance:com.example.mytestcase.AppTest@59662a0b]" started-at="2025-10-05T12:52:30 IST" name="setup" finished-at="2025-10-05T12:52:30 IST" duration-ms="10" status="PASS">
          <reporter-output>
          </reporter-output>
        </test-method> <!-- setup -->
        <test-method signature="testFailCase()[pri:0, instance:com.example.mytestcase.AppTest@59662a0b]" started-at="2025-10-05T12:52:30 IST" name="testFailCase" finished-at="2025-10-05T12:52:30 IST" duration-ms="16" status="FAIL">
          <exception class="java.lang.AssertionError">
            <message>
              <![CDATA[Intentional failure for demo expected [true] but found [false]]]>
            </message>
            <full-stacktrace>
              <![CDATA[java.lang.AssertionError: Intentional failure for demo expected [true] but found [false]
at org.testng.Assert.fail(Assert.java:111)
at org.testng.Assert.failNotEquals(Assert.java:1578)
at org.testng.Assert.assertTrue(Assert.java:57)
at com.example.mytestcase.AppTest.testFailCase(AppTest.java:31)
at java.base/jdk.internal.reflect.DirectMethodHandleAccessor.invoke(DirectMethodHandleAccessor.java:103)
at java.base/java.lang.reflect.Method.invoke(Method.java:580)
at org.testng.internal.invokers.MethodInvocationHelper.invokeMethod(MethodInvocationHelper.java:141)
at org.testng.internal.invokers.TestInvoker.invokeMethod(TestInvoker.java:686)
at org.testng.internal.invokers.TestInvoker.invokeTestMethod(TestInvoker.java:230)
at org.testng.internal.invokers.MethodRunner.runInSequence(MethodRunner.java:63)
at org.testng.internal.invokers.TestInvoker$MethodInvocationAgent.invoke(TestInvoker.java:992)
at org.testng.internal.invokers.TestInvoker.invokeTestMethods(TestInvoker.java:203)
at org.testng.internal.invokers.TestMethodWorker.invokeTestMethods(TestMethodWorker.java:154)
at org.testng.internal.invokers.TestMethodWorker.run(TestMethodWorker.java:134)
at java.base/java.util.ArrayList.forEach(ArrayList.java:1596)
at org.testng.TestRunner.privateRun(TestRunner.java:739)
at org.testng.TestRunner.run(TestRunner.java:614)
at org.testng.SuiteRunner.runTest(SuiteRunner.java:421)
at org.testng.SuiteRunner.runSequentially(SuiteRunner.java:413)
at org.testng.SuiteRunner.privateRun(SuiteRunner.java:373)
at org.testng.SuiteRunner.run(SuiteRunner.java:312)
at org.testng.SuiteRunnerWorker.runSuite(SuiteRunnerWorker.java:52)
at org.testng.SuiteRunnerWorker.run(SuiteRunnerWorker.java:95)
at org.testng.TestNG.runSuitesSequentially(TestNG.java:1274)
at org.testng.TestNG.runSuitesLocally(TestNG.java:1208)
at org.testng.TestNG.runSuites(TestNG.java:1112)
at org.testng.TestNG.run(TestNG.java:1079)
at org.testng.remote.AbstractRemoteTestNG.run(AbstractRemoteTestNG.java:115)
at org.testng.remote.RemoteTestNG.initAndRun(RemoteTestNG.java:293)
at org.testng.remote.RemoteTestNG.main(RemoteTestNG.java:91)
]]>
            </full-stacktrace>
          </exception> <!-- java.lang.AssertionError -->
          <reporter-output>
          </reporter-output>
        </test-method> <!-- testFailCase -->
        <test-method signature="testHello()[pri:0, instance:com.example.mytestcase.AppTest@59662a0b]" started-at="2025-10-05T12:52:30 IST" name="testHello" finished-at="2025-10-05T12:52:30 IST" duration-ms="2" status="PASS">
          <reporter-output>
          </reporter-output>
        </test-method> <!-- testHello -->
      </class> <!-- com.example.mytestcase.AppTest -->
    </test> <!-- SampleTest -->
  </suite> <!-- SampleTestSuite -->
</testng-results>
